<?xml version="1.0" encoding="UTF-8"?>
<testng-results skipped="0" failed="2" total="2" passed="0">
  <reporter-output>
  </reporter-output>
  <suite name="Default suite" duration-ms="29357" started-at="2017-11-21T09:37:36Z" finished-at="2017-11-21T09:38:05Z">
    <groups>
    </groups>
    <test name="Default test" duration-ms="29357" started-at="2017-11-21T09:37:36Z" finished-at="2017-11-21T09:38:05Z">
      <class name="testCases.Day5">
        <test-method status="FAIL" signature="ValidCredentials(java.lang.String, java.lang.String)[pri:0, instance:testCases.Day5@153acfe]" name="ValidCredentials" duration-ms="16147" started-at="2017-11-21T15:07:36Z" data-provider="credentials" finished-at="2017-11-21T15:07:52Z">
          <params>
            <param index="0">
              <value>
                <![CDATA[mngr104786]]>
              </value>
            </param>
            <param index="1">
              <value>
                <![CDATA[hupAguh]]>
              </value>
            </param>
          </params>
          <exception class="org.openqa.selenium.TimeoutException">
            <message>
              <![CDATA[Expected condition failed: waiting for alert to be present (tried for 1 second(s) with 500 MILLISECONDS interval)
Build info: version: '3.7.1', revision: '8a0099a', time: '2017-11-06T21:01:39.354Z'
System info: host: 'EBII346F0', ip: '172.25.114.26', os.name: 'Windows 7', os.arch: 'x86', os.version: '6.1', java.version: '1.8.0_102'
Driver info: org.openqa.selenium.firefox.FirefoxDriver
Capabilities {acceptInsecureCerts: true, browserName: firefox, browserVersion: 57.0, javascriptEnabled: true, moz:accessibilityChecks: false, moz:headless: false, moz:processID: 904, moz:profile: C:\Users\28891\AppData\Loca..., moz:webdriverClick: false, pageLoadStrategy: normal, platform: XP, platformName: XP, platformVersion: 6.1, rotatable: false, timeouts: {implicit: 0, pageLoad: 300000, script: 30000}}
Session ID: 4a0e0ee9-b6a0-49a1-be2e-faa1387f6ac3]]>
            </message>
            <full-stacktrace>
              <![CDATA[org.openqa.selenium.TimeoutException: Expected condition failed: waiting for alert to be present (tried for 1 second(s) with 500 MILLISECONDS interval)
Build info: version: '3.7.1', revision: '8a0099a', time: '2017-11-06T21:01:39.354Z'
System info: host: 'EBII346F0', ip: '172.25.114.26', os.name: 'Windows 7', os.arch: 'x86', os.version: '6.1', java.version: '1.8.0_102'
Driver info: org.openqa.selenium.firefox.FirefoxDriver
Capabilities {acceptInsecureCerts: true, browserName: firefox, browserVersion: 57.0, javascriptEnabled: true, moz:accessibilityChecks: false, moz:headless: false, moz:processID: 904, moz:profile: C:\Users\28891\AppData\Loca..., moz:webdriverClick: false, pageLoadStrategy: normal, platform: XP, platformName: XP, platformVersion: 6.1, rotatable: false, timeouts: {implicit: 0, pageLoad: 300000, script: 30000}}
Session ID: 4a0e0ee9-b6a0-49a1-be2e-faa1387f6ac3
	at org.openqa.selenium.support.ui.WebDriverWait.timeoutException(WebDriverWait.java:82)
	at org.openqa.selenium.support.ui.FluentWait.until(FluentWait.java:231)
	at testCases.Day5.ValidCredentials(Day5.java:46)
	at sun.reflect.NativeMethodAccessorImpl.invoke0(Native Method)
	at sun.reflect.NativeMethodAccessorImpl.invoke(Unknown Source)
	at sun.reflect.DelegatingMethodAccessorImpl.invoke(Unknown Source)
	at java.lang.reflect.Method.invoke(Unknown Source)
	at org.testng.internal.MethodInvocationHelper.invokeMethod(MethodInvocationHelper.java:100)
	at org.testng.internal.Invoker.invokeMethod(Invoker.java:646)
	at org.testng.internal.Invoker.invokeTestMethod(Invoker.java:811)
	at org.testng.internal.Invoker.invokeTestMethods(Invoker.java:1129)
	at org.testng.internal.TestMethodWorker.invokeTestMethods(TestMethodWorker.java:129)
	at org.testng.internal.TestMethodWorker.run(TestMethodWorker.java:112)
	at org.testng.TestRunner.privateRun(TestRunner.java:746)
	at org.testng.TestRunner.run(TestRunner.java:600)
	at org.testng.SuiteRunner.runTest(SuiteRunner.java:366)
	at org.testng.SuiteRunner.runSequentially(SuiteRunner.java:361)
	at org.testng.SuiteRunner.privateRun(SuiteRunner.java:319)
	at org.testng.SuiteRunner.run(SuiteRunner.java:268)
	at org.testng.SuiteRunnerWorker.runSuite(SuiteRunnerWorker.java:52)
	at org.testng.SuiteRunnerWorker.run(SuiteRunnerWorker.java:86)
	at org.testng.TestNG.runSuitesSequentially(TestNG.java:1264)
	at org.testng.TestNG.runSuitesLocally(TestNG.java:1189)
	at org.testng.TestNG.runSuites(TestNG.java:1104)
	at org.testng.TestNG.run(TestNG.java:1076)
	at org.testng.remote.AbstractRemoteTestNG.run(AbstractRemoteTestNG.java:126)
	at org.testng.remote.RemoteTestNG.initAndRun(RemoteTestNG.java:152)
	at org.testng.remote.RemoteTestNG.main(RemoteTestNG.java:57)
]]>
            </full-stacktrace>
          </exception> <!-- org.openqa.selenium.TimeoutException -->
          <reporter-output>
          </reporter-output>
        </test-method> <!-- ValidCredentials -->
        <test-method status="FAIL" signature="ValidCredentials(java.lang.String, java.lang.String)[pri:0, instance:testCases.Day5@153acfe]" name="ValidCredentials" duration-ms="13150" started-at="2017-11-21T15:07:52Z" data-provider="credentials" finished-at="2017-11-21T15:08:05Z">
          <params>
            <param index="0">
              <value>
                <![CDATA[Dummy]]>
              </value>
            </param>
            <param index="1">
              <value>
                <![CDATA[Dummy]]>
              </value>
            </param>
          </params>
          <exception class="java.lang.NullPointerException">
            <full-stacktrace>
              <![CDATA[java.lang.NullPointerException
	at base.IElement.getText(IElement.java:126)
	at testCases.Day5.ValidCredentials(Day5.java:48)
	at sun.reflect.NativeMethodAccessorImpl.invoke0(Native Method)
	at sun.reflect.NativeMethodAccessorImpl.invoke(Unknown Source)
	at sun.reflect.DelegatingMethodAccessorImpl.invoke(Unknown Source)
	at java.lang.reflect.Method.invoke(Unknown Source)
	at org.testng.internal.MethodInvocationHelper.invokeMethod(MethodInvocationHelper.java:100)
	at org.testng.internal.Invoker.invokeMethod(Invoker.java:646)
	at org.testng.internal.Invoker.invokeTestMethod(Invoker.java:811)
	at org.testng.internal.Invoker.invokeTestMethods(Invoker.java:1129)
	at org.testng.internal.TestMethodWorker.invokeTestMethods(TestMethodWorker.java:129)
	at org.testng.internal.TestMethodWorker.run(TestMethodWorker.java:112)
	at org.testng.TestRunner.privateRun(TestRunner.java:746)
	at org.testng.TestRunner.run(TestRunner.java:600)
	at org.testng.SuiteRunner.runTest(SuiteRunner.java:366)
	at org.testng.SuiteRunner.runSequentially(SuiteRunner.java:361)
	at org.testng.SuiteRunner.privateRun(SuiteRunner.java:319)
	at org.testng.SuiteRunner.run(SuiteRunner.java:268)
	at org.testng.SuiteRunnerWorker.runSuite(SuiteRunnerWorker.java:52)
	at org.testng.SuiteRunnerWorker.run(SuiteRunnerWorker.java:86)
	at org.testng.TestNG.runSuitesSequentially(TestNG.java:1264)
	at org.testng.TestNG.runSuitesLocally(TestNG.java:1189)
	at org.testng.TestNG.runSuites(TestNG.java:1104)
	at org.testng.TestNG.run(TestNG.java:1076)
	at org.testng.remote.AbstractRemoteTestNG.run(AbstractRemoteTestNG.java:126)
	at org.testng.remote.RemoteTestNG.initAndRun(RemoteTestNG.java:152)
	at org.testng.remote.RemoteTestNG.main(RemoteTestNG.java:57)
]]>
            </full-stacktrace>
          </exception> <!-- java.lang.NullPointerException -->
          <reporter-output>
          </reporter-output>
        </test-method> <!-- ValidCredentials -->
      </class> <!-- testCases.Day5 -->
    </test> <!-- Default test -->
  </suite> <!-- Default suite -->
</testng-results>
